2024-06-25 13:20:35,344 INFO    StreamThr :1699029 [internal.py:wandb_internal():85] W&B internal server running at pid: 1699029, started at: 2024-06-25 13:20:35.344046
2024-06-25 13:20:35,346 DEBUG   HandlerThread:1699029 [handler.py:handle_request():158] handle_request: status
2024-06-25 13:20:35,354 INFO    WriterThread:1699029 [datastore.py:open_for_write():87] open: /net/tscratch/people/plgjoanfr97/Files/GitRepos/AstraZeneca/Code/wandb/run-20240625_132035-h6iah19j/run-h6iah19j.wandb
2024-06-25 13:20:35,355 DEBUG   SenderThread:1699029 [sender.py:send():379] send: header
2024-06-25 13:20:35,355 DEBUG   SenderThread:1699029 [sender.py:send():379] send: run
2024-06-25 13:20:35,358 INFO    SenderThread:1699029 [sender.py:_setup_resume():749] checking resume status for joansano/U-Net/h6iah19j
2024-06-25 13:20:35,878 ERROR   SenderThread:1699029 [internal_api.py:execute():344] 404 response executing GraphQL.
2024-06-25 13:20:35,878 ERROR   SenderThread:1699029 [internal_api.py:execute():345] {"errors":[{"message":"project not found","path":["upsertBucket"]}],"data":{"upsertBucket":null}}
2024-06-25 13:20:35,879 ERROR   SenderThread:1699029 [sender.py:send_run():1009] It appears that you do not have permission to access the requested resource. Please reach out to the project owner to grant you access. If you have the correct permissions, verify that there are no issues with your networking setup.(Error 404: Not Found)
Traceback (most recent call last):
  File "/net/tscratch/people/plgjoanfr97/conda-envs/astra/lib/python3.12/site-packages/wandb/sdk/lib/retry.py", line 131, in __call__
    result = self._call_fn(*args, **kwargs)
             ^^^^^^^^^^^^^^^^^^^^^^^^^^^^^^
  File "/net/tscratch/people/plgjoanfr97/conda-envs/astra/lib/python3.12/site-packages/wandb/sdk/internal/internal_api.py", line 340, in execute
    return self.client.execute(*args, **kwargs)  # type: ignore
           ^^^^^^^^^^^^^^^^^^^^^^^^^^^^^^^^^^^^
  File "/net/tscratch/people/plgjoanfr97/conda-envs/astra/lib/python3.12/site-packages/wandb/vendor/gql-0.2.0/wandb_gql/client.py", line 52, in execute
    result = self._get_result(document, *args, **kwargs)
             ^^^^^^^^^^^^^^^^^^^^^^^^^^^^^^^^^^^^^^^^^^^
  File "/net/tscratch/people/plgjoanfr97/conda-envs/astra/lib/python3.12/site-packages/wandb/vendor/gql-0.2.0/wandb_gql/client.py", line 60, in _get_result
    return self.transport.execute(document, *args, **kwargs)
           ^^^^^^^^^^^^^^^^^^^^^^^^^^^^^^^^^^^^^^^^^^^^^^^^^
  File "/net/tscratch/people/plgjoanfr97/conda-envs/astra/lib/python3.12/site-packages/wandb/sdk/lib/gql_request.py", line 59, in execute
    request.raise_for_status()
  File "/net/tscratch/people/plgjoanfr97/conda-envs/astra/lib/python3.12/site-packages/requests/models.py", line 1024, in raise_for_status
    raise HTTPError(http_error_msg, response=self)
requests.exceptions.HTTPError: 404 Client Error: Not Found for url: https://api.wandb.ai/graphql

During handling of the above exception, another exception occurred:

Traceback (most recent call last):
  File "/net/tscratch/people/plgjoanfr97/conda-envs/astra/lib/python3.12/site-packages/wandb/sdk/internal/sender.py", line 1007, in send_run
    server_run = self._init_run(run, config_value_dict)
                 ^^^^^^^^^^^^^^^^^^^^^^^^^^^^^^^^^^^^^^
  File "/net/tscratch/people/plgjoanfr97/conda-envs/astra/lib/python3.12/site-packages/wandb/sdk/internal/sender.py", line 1079, in _init_run
    server_run, inserted, server_messages = self._api.upsert_run(
                                            ^^^^^^^^^^^^^^^^^^^^^
  File "/net/tscratch/people/plgjoanfr97/conda-envs/astra/lib/python3.12/site-packages/wandb/apis/normalize.py", line 73, in wrapper
    raise err
  File "/net/tscratch/people/plgjoanfr97/conda-envs/astra/lib/python3.12/site-packages/wandb/apis/normalize.py", line 41, in wrapper
    return func(*args, **kwargs)
           ^^^^^^^^^^^^^^^^^^^^^
  File "/net/tscratch/people/plgjoanfr97/conda-envs/astra/lib/python3.12/site-packages/wandb/sdk/internal/internal_api.py", line 2190, in upsert_run
    response = self.gql(
               ^^^^^^^^^
  File "/net/tscratch/people/plgjoanfr97/conda-envs/astra/lib/python3.12/site-packages/wandb/sdk/internal/internal_api.py", line 312, in gql
    ret = self._retry_gql(
          ^^^^^^^^^^^^^^^^
  File "/net/tscratch/people/plgjoanfr97/conda-envs/astra/lib/python3.12/site-packages/wandb/sdk/lib/retry.py", line 147, in __call__
    retry_timedelta_triggered = check_retry_fn(e)
                                ^^^^^^^^^^^^^^^^^
  File "/net/tscratch/people/plgjoanfr97/conda-envs/astra/lib/python3.12/site-packages/wandb/util.py", line 968, in check_retry_fn
    return fallback_retry_fn(e)
           ^^^^^^^^^^^^^^^^^^^^
  File "/net/tscratch/people/plgjoanfr97/conda-envs/astra/lib/python3.12/site-packages/wandb/util.py", line 910, in no_retry_auth
    raise CommError(
wandb.errors.CommError: It appears that you do not have permission to access the requested resource. Please reach out to the project owner to grant you access. If you have the correct permissions, verify that there are no issues with your networking setup.(Error 404: Not Found)
2024-06-25 13:20:36,005 DEBUG   HandlerThread:1699029 [handler.py:handle_request():158] handle_request: shutdown
2024-06-25 13:20:36,005 INFO    HandlerThread:1699029 [handler.py:finish():882] shutting down handler
2024-06-25 13:20:36,355 INFO    WriterThread:1699029 [datastore.py:close():296] close: /net/tscratch/people/plgjoanfr97/Files/GitRepos/AstraZeneca/Code/wandb/run-20240625_132035-h6iah19j/run-h6iah19j.wandb
2024-06-25 13:20:36,885 INFO    SenderThread:1699029 [sender.py:finish():1608] shutting down sender
